{
  "start_time": 1759235203.891178,
  "categories": {
    "unit": {
      "category": "unit",
      "success": false,
      "returncode": 4,
      "duration": 5.401770114898682,
      "stdout": "============================= test session starts ==============================\nplatform darwin -- Python 3.13.7, pytest-8.4.1, pluggy-1.6.0 -- /opt/homebrew/opt/python@3.13/bin/python3.13\ncachedir: .pytest_cache\nmetadata: {'Python': '3.13.7', 'Platform': 'macOS-26.0.1-arm64-arm-64bit-Mach-O', 'Packages': {'pytest': '8.4.1', 'pluggy': '1.6.0'}, 'Plugins': {'anyio': '4.9.0', 'html': '4.1.1', 'asyncio': '1.1.0', 'xdist': '3.8.0', 'metadata': '3.1.1', 'cov': '6.2.1', 'mock': '3.14.1'}}\nrootdir: /Users/Mark/Research/CAAIN_Soil_Hub/CAAIN_Soil_Hub_ChatGPT_Kiro/services/fertilizer-application\nconfigfile: pytest.ini\nplugins: anyio-4.9.0, html-4.1.1, asyncio-1.1.0, xdist-3.8.0, metadata-3.1.1, cov-6.2.1, mock-3.14.1\nasyncio: mode=Mode.AUTO, asyncio_default_fixture_loop_scope=None, asyncio_default_test_loop_scope=function\ncollecting ... collected 221 items / 6 errors\n\n==================================== ERRORS ====================================\n___________ ERROR collecting tests/test_adaptive_learning_service.py ___________\nImportError while importing test module '/Users/Mark/Research/CAAIN_Soil_Hub/CAAIN_Soil_Hub_ChatGPT_Kiro/services/fertilizer-application/tests/test_adaptive_learning_service.py'.\nHint: make sure your test modules/packages have valid Python names.\nTraceback:\n/opt/homebrew/lib/python3.13/site-packages/_pytest/python.py:498: in importtestmodule\n    mod = import_path(\n/opt/homebrew/lib/python3.13/site-packages/_pytest/pathlib.py:587: in import_path\n    importlib.import_module(module_name)\n/opt/homebrew/Cellar/python@3.13/3.13.7/Frameworks/Python.framework/Versions/3.13/lib/python3.13/importlib/__init__.py:88: in import_module\n    return _bootstrap._gcd_import(name[level:], package, level)\n           ^^^^^^^^^^^^^^^^^^^^^^^^^^^^^^^^^^^^^^^^^^^^^^^^^^^^\n<frozen importlib._bootstrap>:1387: in _gcd_import\n    ???\n<frozen importlib._bootstrap>:1360: in _find_and_load\n    ???\n<frozen importlib._bootstrap>:1331: in _find_and_load_unlocked\n    ???\n<frozen importlib._bootstrap>:935: in _load_unlocked\n    ???\n/opt/homebrew/lib/python3.13/site-packages/_pytest/assertion/rewrite.py:186: in exec_module\n    exec(co, module.__dict__)\ntests/test_adaptive_learning_service.py:15: in <module>\n    from src.services.adaptive_learning_service import (\nsrc/services/adaptive_learning_service.py:35: in <module>\n    from src.servicesgoal_based_recommendation_engine import GoalBasedRecommendationEngine, OptimizationGoal\nE   ModuleNotFoundError: No module named 'src.servicesgoal_based_recommendation_engine'\n________ ERROR collecting tests/test_advanced_application_endpoints.py _________\ntests/test_advanced_application_endpoints.py:13: in <module>\n    from src.main import app\nsrc/main.py:17: in <module>\n    from src.api.crop_response_routes import router as crop_response_router\nsrc/api/crop_response_routes.py:32: in <module>\n    @router.post(\"/optimize-methods\", response_model=List[Dict[str, Any]])\n     ^^^^^^^^^^^^^^^^^^^^^^^^^^^^^^^^^^^^^^^^^^^^^^^^^^^^^^^^^^^^^^^^^^^^^\n/opt/homebrew/lib/python3.13/site-packages/fastapi/routing.py:995: in decorator\n    self.add_api_route(\n/opt/homebrew/lib/python3.13/site-packages/fastapi/routing.py:934: in add_api_route\n    route = route_class(\n/opt/homebrew/lib/python3.13/site-packages/fastapi/routing.py:555: in __init__\n    self.dependant = get_dependant(path=self.path_format, call=self.endpoint)\n                     ^^^^^^^^^^^^^^^^^^^^^^^^^^^^^^^^^^^^^^^^^^^^^^^^^^^^^^^^\n/opt/homebrew/lib/python3.13/site-packages/fastapi/dependencies/utils.py:285: in get_dependant\n    param_details = analyze_param(\n/opt/homebrew/lib/python3.13/site-packages/fastapi/dependencies/utils.py:502: in analyze_param\n    is_scalar_field(field)\nE   AssertionError\n_________ ERROR collecting tests/test_algorithm_validation_service.py __________\nImportError while importing test module '/Users/Mark/Research/CAAIN_Soil_Hub/CAAIN_Soil_Hub_ChatGPT_Kiro/services/fertilizer-application/tests/test_algorithm_validation_service.py'.\nHint: make sure your test modules/packages have valid Python names.\nTraceback:\n/opt/homebrew/lib/python3.13/site-packages/_pytest/python.py:498: in importtestmodule\n    mod = import_path(\n/opt/homebrew/lib/python3.13/site-packages/_pytest/pathlib.py:587: in import_path\n    importlib.import_module(module_name)\n/opt/homebrew/Cellar/python@3.13/3.13.7/Frameworks/Python.framework/Versions/3.13/lib/python3.13/importlib/__init__.py:88: in import_module\n    return _bootstrap._gcd_import(name[level:], package, level)\n           ^^^^^^^^^^^^^^^^^^^^^^^^^^^^^^^^^^^^^^^^^^^^^^^^^^^^\n<frozen importlib._bootstrap>:1387: in _gcd_import\n    ???\n<frozen importlib._bootstrap>:1360: in _find_and_load\n    ???\n<frozen importlib._bootstrap>:1331: in _find_and_load_unlocked\n    ???\n<frozen importlib._bootstrap>:935: in _load_unlocked\n    ???\n/opt/homebrew/lib/python3.13/site-packages/_pytest/assertion/rewrite.py:186: in exec_module\n    exec(co, module.__dict__)\ntests/test_algorithm_validation_service.py:26: in <module>\n    from src.services.sophisticated_method_selection_service import (\nsrc/services/sophisticated_method_selection_service.py:29: in <module>\n    import cvxpy as cp\nE   ModuleNotFoundError: No module named 'cvxpy'\n______________________ ERROR collecting tests/test_api.py ______________________\ntests/test_api.py:10: in <module>\n    from src.main import app\nsrc/main.py:17: in <module>\n    from src.api.crop_response_routes import router as crop_response_router\nsrc/api/crop_response_routes.py:32: in <module>\n    @router.post(\"/optimize-methods\", response_model=List[Dict[str, Any]])\n     ^^^^^^^^^^^^^^^^^^^^^^^^^^^^^^^^^^^^^^^^^^^^^^^^^^^^^^^^^^^^^^^^^^^^^\n/opt/homebrew/lib/python3.13/site-packages/fastapi/routing.py:995: in decorator\n    self.add_api_route(\n/opt/homebrew/lib/python3.13/site-packages/fastapi/routing.py:934: in add_api_route\n    route = route_class(\n/opt/homebrew/lib/python3.13/site-packages/fastapi/routing.py:555: in __init__\n    self.dependant = get_dependant(path=self.path_format, call=self.endpoint)\n                     ^^^^^^^^^^^^^^^^^^^^^^^^^^^^^^^^^^^^^^^^^^^^^^^^^^^^^^^^\n/opt/homebrew/lib/python3.13/site-packages/fastapi/dependencies/utils.py:285: in get_dependant\n    param_details = analyze_param(\n/opt/homebrew/lib/python3.13/site-packages/fastapi/dependencies/utils.py:502: in analyze_param\n    is_scalar_field(field)\nE   AssertionError\n_______________ ERROR collecting tests/test_education_service.py _______________\nImportError while importing test module '/Users/Mark/Research/CAAIN_Soil_Hub/CAAIN_Soil_Hub_ChatGPT_Kiro/services/fertilizer-application/tests/test_education_service.py'.\nHint: make sure your test modules/packages have valid Python names.\nTraceback:\n/opt/homebrew/lib/python3.13/site-packages/_pytest/python.py:498: in importtestmodule\n    mod = import_path(\n/opt/homebrew/lib/python3.13/site-packages/_pytest/pathlib.py:587: in import_path\n    importlib.import_module(module_name)\n/opt/homebrew/Cellar/python@3.13/3.13.7/Frameworks/Python.framework/Versions/3.13/lib/python3.13/importlib/__init__.py:88: in import_module\n    return _bootstrap._gcd_import(name[level:], package, level)\n           ^^^^^^^^^^^^^^^^^^^^^^^^^^^^^^^^^^^^^^^^^^^^^^^^^^^^\n<frozen importlib._bootstrap>:1387: in _gcd_import\n    ???\n<frozen importlib._bootstrap>:1360: in _find_and_load\n    ???\n<frozen importlib._bootstrap>:1331: in _find_and_load_unlocked\n    ???\n<frozen importlib._bootstrap>:935: in _load_unlocked\n    ???\n/opt/homebrew/lib/python3.13/site-packages/_pytest/assertion/rewrite.py:186: in exec_module\n    exec(co, module.__dict__)\ntests/test_education_service.py:15: in <module>\n    from src.services.education_service import EducationService\nsrc/services/education_service.py:16: in <module>\n    from src.models.educational_models import (\nE   ImportError: cannot import name 'UserProfile' from 'src.models.educational_models' (/Users/Mark/Research/CAAIN_Soil_Hub/CAAIN_Soil_Hub_ChatGPT_Kiro/services/fertilizer-application/src/models/educational_models.py)\n_____________ ERROR collecting tests/test_knowledge_assessment.py ______________\nImportError while importing test module '/Users/Mark/Research/CAAIN_Soil_Hub/CAAIN_Soil_Hub_ChatGPT_Kiro/services/fertilizer-application/tests/test_knowledge_assessment.py'.\nHint: make sure your test modules/packages have valid Python names.\nTraceback:\n/opt/homebrew/lib/python3.13/site-packages/_pytest/python.py:498: in importtestmodule\n    mod = import_path(\n/opt/homebrew/lib/python3.13/site-packages/_pytest/pathlib.py:587: in import_path\n    importlib.import_module(module_name)\n/opt/homebrew/Cellar/python@3.13/3.13.7/Frameworks/Python.framework/Versions/3.13/lib/python3.13/importlib/__init__.py:88: in import_module\n    return _bootstrap._gcd_import(name[level:], package, level)\n           ^^^^^^^^^^^^^^^^^^^^^^^^^^^^^^^^^^^^^^^^^^^^^^^^^^^^\n<frozen importlib._bootstrap>:1387: in _gcd_import\n    ???\n<frozen importlib._bootstrap>:1360: in _find_and_load\n    ???\n<frozen importlib._bootstrap>:1331: in _find_and_load_unlocked\n    ???\n<frozen importlib._bootstrap>:935: in _load_unlocked\n    ???\n/opt/homebrew/lib/python3.13/site-packages/_pytest/assertion/rewrite.py:186: in exec_module\n    exec(co, module.__dict__)\ntests/test_knowledge_assessment.py:14: in <module>\n    from src.models.educational_models import (\nE   ImportError: cannot import name 'CertificationStatus' from 'src.models.educational_models' (/Users/Mark/Research/CAAIN_Soil_Hub/CAAIN_Soil_Hub_ChatGPT_Kiro/services/fertilizer-application/src/models/educational_models.py)\n- generated xml file: /Users/Mark/Research/CAAIN_Soil_Hub/CAAIN_Soil_Hub_ChatGPT_Kiro/services/fertilizer-application/test_reports/unit_results.xml -\n- Generated html report: file:///Users/Mark/Research/CAAIN_Soil_Hub/CAAIN_Soil_Hub_ChatGPT_Kiro/services/fertilizer-application/test_reports/unit_report.html -\n=========================== short test summary info ============================\nERROR tests/test_adaptive_learning_service.py\nERROR tests/test_advanced_application_endpoints.py - AssertionError\nERROR tests/test_algorithm_validation_service.py\nERROR tests/test_api.py - AssertionError\nERROR tests/test_education_service.py\nERROR tests/test_knowledge_assessment.py\n======================== 2 warnings, 6 errors in 1.81s =========================\n",
      "stderr": "ERROR: Wrong expression passed to '-k': test_*.py: at column 6: unexpected character \"*\"\n\n",
      "total_tests": 0,
      "passed_tests": 0,
      "failed_tests": 0,
      "skipped_tests": 0
    },
    "integration": {
      "category": "integration",
      "success": false,
      "returncode": 4,
      "duration": 4.77117395401001,
      "stdout": "============================= test session starts ==============================\nplatform darwin -- Python 3.13.7, pytest-8.4.1, pluggy-1.6.0 -- /opt/homebrew/opt/python@3.13/bin/python3.13\ncachedir: .pytest_cache\nmetadata: {'Python': '3.13.7', 'Platform': 'macOS-26.0.1-arm64-arm-64bit-Mach-O', 'Packages': {'pytest': '8.4.1', 'pluggy': '1.6.0'}, 'Plugins': {'anyio': '4.9.0', 'html': '4.1.1', 'asyncio': '1.1.0', 'xdist': '3.8.0', 'metadata': '3.1.1', 'cov': '6.2.1', 'mock': '3.14.1'}}\nrootdir: /Users/Mark/Research/CAAIN_Soil_Hub/CAAIN_Soil_Hub_ChatGPT_Kiro/services/fertilizer-application\nconfigfile: pytest.ini\nplugins: anyio-4.9.0, html-4.1.1, asyncio-1.1.0, xdist-3.8.0, metadata-3.1.1, cov-6.2.1, mock-3.14.1\nasyncio: mode=Mode.AUTO, asyncio_default_fixture_loop_scope=None, asyncio_default_test_loop_scope=function\ncollecting ... collected 221 items / 6 errors\n\n==================================== ERRORS ====================================\n___________ ERROR collecting tests/test_adaptive_learning_service.py ___________\nImportError while importing test module '/Users/Mark/Research/CAAIN_Soil_Hub/CAAIN_Soil_Hub_ChatGPT_Kiro/services/fertilizer-application/tests/test_adaptive_learning_service.py'.\nHint: make sure your test modules/packages have valid Python names.\nTraceback:\n/opt/homebrew/lib/python3.13/site-packages/_pytest/python.py:498: in importtestmodule\n    mod = import_path(\n/opt/homebrew/lib/python3.13/site-packages/_pytest/pathlib.py:587: in import_path\n    importlib.import_module(module_name)\n/opt/homebrew/Cellar/python@3.13/3.13.7/Frameworks/Python.framework/Versions/3.13/lib/python3.13/importlib/__init__.py:88: in import_module\n    return _bootstrap._gcd_import(name[level:], package, level)\n           ^^^^^^^^^^^^^^^^^^^^^^^^^^^^^^^^^^^^^^^^^^^^^^^^^^^^\n<frozen importlib._bootstrap>:1387: in _gcd_import\n    ???\n<frozen importlib._bootstrap>:1360: in _find_and_load\n    ???\n<frozen importlib._bootstrap>:1331: in _find_and_load_unlocked\n    ???\n<frozen importlib._bootstrap>:935: in _load_unlocked\n    ???\n/opt/homebrew/lib/python3.13/site-packages/_pytest/assertion/rewrite.py:186: in exec_module\n    exec(co, module.__dict__)\ntests/test_adaptive_learning_service.py:15: in <module>\n    from src.services.adaptive_learning_service import (\nsrc/services/adaptive_learning_service.py:35: in <module>\n    from src.servicesgoal_based_recommendation_engine import GoalBasedRecommendationEngine, OptimizationGoal\nE   ModuleNotFoundError: No module named 'src.servicesgoal_based_recommendation_engine'\n________ ERROR collecting tests/test_advanced_application_endpoints.py _________\ntests/test_advanced_application_endpoints.py:13: in <module>\n    from src.main import app\nsrc/main.py:17: in <module>\n    from src.api.crop_response_routes import router as crop_response_router\nsrc/api/crop_response_routes.py:32: in <module>\n    @router.post(\"/optimize-methods\", response_model=List[Dict[str, Any]])\n     ^^^^^^^^^^^^^^^^^^^^^^^^^^^^^^^^^^^^^^^^^^^^^^^^^^^^^^^^^^^^^^^^^^^^^\n/opt/homebrew/lib/python3.13/site-packages/fastapi/routing.py:995: in decorator\n    self.add_api_route(\n/opt/homebrew/lib/python3.13/site-packages/fastapi/routing.py:934: in add_api_route\n    route = route_class(\n/opt/homebrew/lib/python3.13/site-packages/fastapi/routing.py:555: in __init__\n    self.dependant = get_dependant(path=self.path_format, call=self.endpoint)\n                     ^^^^^^^^^^^^^^^^^^^^^^^^^^^^^^^^^^^^^^^^^^^^^^^^^^^^^^^^\n/opt/homebrew/lib/python3.13/site-packages/fastapi/dependencies/utils.py:285: in get_dependant\n    param_details = analyze_param(\n/opt/homebrew/lib/python3.13/site-packages/fastapi/dependencies/utils.py:502: in analyze_param\n    is_scalar_field(field)\nE   AssertionError\n_________ ERROR collecting tests/test_algorithm_validation_service.py __________\nImportError while importing test module '/Users/Mark/Research/CAAIN_Soil_Hub/CAAIN_Soil_Hub_ChatGPT_Kiro/services/fertilizer-application/tests/test_algorithm_validation_service.py'.\nHint: make sure your test modules/packages have valid Python names.\nTraceback:\n/opt/homebrew/lib/python3.13/site-packages/_pytest/python.py:498: in importtestmodule\n    mod = import_path(\n/opt/homebrew/lib/python3.13/site-packages/_pytest/pathlib.py:587: in import_path\n    importlib.import_module(module_name)\n/opt/homebrew/Cellar/python@3.13/3.13.7/Frameworks/Python.framework/Versions/3.13/lib/python3.13/importlib/__init__.py:88: in import_module\n    return _bootstrap._gcd_import(name[level:], package, level)\n           ^^^^^^^^^^^^^^^^^^^^^^^^^^^^^^^^^^^^^^^^^^^^^^^^^^^^\n<frozen importlib._bootstrap>:1387: in _gcd_import\n    ???\n<frozen importlib._bootstrap>:1360: in _find_and_load\n    ???\n<frozen importlib._bootstrap>:1331: in _find_and_load_unlocked\n    ???\n<frozen importlib._bootstrap>:935: in _load_unlocked\n    ???\n/opt/homebrew/lib/python3.13/site-packages/_pytest/assertion/rewrite.py:186: in exec_module\n    exec(co, module.__dict__)\ntests/test_algorithm_validation_service.py:26: in <module>\n    from src.services.sophisticated_method_selection_service import (\nsrc/services/sophisticated_method_selection_service.py:29: in <module>\n    import cvxpy as cp\nE   ModuleNotFoundError: No module named 'cvxpy'\n______________________ ERROR collecting tests/test_api.py ______________________\ntests/test_api.py:10: in <module>\n    from src.main import app\nsrc/main.py:17: in <module>\n    from src.api.crop_response_routes import router as crop_response_router\nsrc/api/crop_response_routes.py:32: in <module>\n    @router.post(\"/optimize-methods\", response_model=List[Dict[str, Any]])\n     ^^^^^^^^^^^^^^^^^^^^^^^^^^^^^^^^^^^^^^^^^^^^^^^^^^^^^^^^^^^^^^^^^^^^^\n/opt/homebrew/lib/python3.13/site-packages/fastapi/routing.py:995: in decorator\n    self.add_api_route(\n/opt/homebrew/lib/python3.13/site-packages/fastapi/routing.py:934: in add_api_route\n    route = route_class(\n/opt/homebrew/lib/python3.13/site-packages/fastapi/routing.py:555: in __init__\n    self.dependant = get_dependant(path=self.path_format, call=self.endpoint)\n                     ^^^^^^^^^^^^^^^^^^^^^^^^^^^^^^^^^^^^^^^^^^^^^^^^^^^^^^^^\n/opt/homebrew/lib/python3.13/site-packages/fastapi/dependencies/utils.py:285: in get_dependant\n    param_details = analyze_param(\n/opt/homebrew/lib/python3.13/site-packages/fastapi/dependencies/utils.py:502: in analyze_param\n    is_scalar_field(field)\nE   AssertionError\n_______________ ERROR collecting tests/test_education_service.py _______________\nImportError while importing test module '/Users/Mark/Research/CAAIN_Soil_Hub/CAAIN_Soil_Hub_ChatGPT_Kiro/services/fertilizer-application/tests/test_education_service.py'.\nHint: make sure your test modules/packages have valid Python names.\nTraceback:\n/opt/homebrew/lib/python3.13/site-packages/_pytest/python.py:498: in importtestmodule\n    mod = import_path(\n/opt/homebrew/lib/python3.13/site-packages/_pytest/pathlib.py:587: in import_path\n    importlib.import_module(module_name)\n/opt/homebrew/Cellar/python@3.13/3.13.7/Frameworks/Python.framework/Versions/3.13/lib/python3.13/importlib/__init__.py:88: in import_module\n    return _bootstrap._gcd_import(name[level:], package, level)\n           ^^^^^^^^^^^^^^^^^^^^^^^^^^^^^^^^^^^^^^^^^^^^^^^^^^^^\n<frozen importlib._bootstrap>:1387: in _gcd_import\n    ???\n<frozen importlib._bootstrap>:1360: in _find_and_load\n    ???\n<frozen importlib._bootstrap>:1331: in _find_and_load_unlocked\n    ???\n<frozen importlib._bootstrap>:935: in _load_unlocked\n    ???\n/opt/homebrew/lib/python3.13/site-packages/_pytest/assertion/rewrite.py:186: in exec_module\n    exec(co, module.__dict__)\ntests/test_education_service.py:15: in <module>\n    from src.services.education_service import EducationService\nsrc/services/education_service.py:16: in <module>\n    from src.models.educational_models import (\nE   ImportError: cannot import name 'UserProfile' from 'src.models.educational_models' (/Users/Mark/Research/CAAIN_Soil_Hub/CAAIN_Soil_Hub_ChatGPT_Kiro/services/fertilizer-application/src/models/educational_models.py)\n_____________ ERROR collecting tests/test_knowledge_assessment.py ______________\nImportError while importing test module '/Users/Mark/Research/CAAIN_Soil_Hub/CAAIN_Soil_Hub_ChatGPT_Kiro/services/fertilizer-application/tests/test_knowledge_assessment.py'.\nHint: make sure your test modules/packages have valid Python names.\nTraceback:\n/opt/homebrew/lib/python3.13/site-packages/_pytest/python.py:498: in importtestmodule\n    mod = import_path(\n/opt/homebrew/lib/python3.13/site-packages/_pytest/pathlib.py:587: in import_path\n    importlib.import_module(module_name)\n/opt/homebrew/Cellar/python@3.13/3.13.7/Frameworks/Python.framework/Versions/3.13/lib/python3.13/importlib/__init__.py:88: in import_module\n    return _bootstrap._gcd_import(name[level:], package, level)\n           ^^^^^^^^^^^^^^^^^^^^^^^^^^^^^^^^^^^^^^^^^^^^^^^^^^^^\n<frozen importlib._bootstrap>:1387: in _gcd_import\n    ???\n<frozen importlib._bootstrap>:1360: in _find_and_load\n    ???\n<frozen importlib._bootstrap>:1331: in _find_and_load_unlocked\n    ???\n<frozen importlib._bootstrap>:935: in _load_unlocked\n    ???\n/opt/homebrew/lib/python3.13/site-packages/_pytest/assertion/rewrite.py:186: in exec_module\n    exec(co, module.__dict__)\ntests/test_knowledge_assessment.py:14: in <module>\n    from src.models.educational_models import (\nE   ImportError: cannot import name 'CertificationStatus' from 'src.models.educational_models' (/Users/Mark/Research/CAAIN_Soil_Hub/CAAIN_Soil_Hub_ChatGPT_Kiro/services/fertilizer-application/src/models/educational_models.py)\n- generated xml file: /Users/Mark/Research/CAAIN_Soil_Hub/CAAIN_Soil_Hub_ChatGPT_Kiro/services/fertilizer-application/test_reports/integration_results.xml -\n- Generated html report: file:///Users/Mark/Research/CAAIN_Soil_Hub/CAAIN_Soil_Hub_ChatGPT_Kiro/services/fertilizer-application/test_reports/integration_report.html -\n=========================== short test summary info ============================\nERROR tests/test_adaptive_learning_service.py\nERROR tests/test_advanced_application_endpoints.py - AssertionError\nERROR tests/test_algorithm_validation_service.py\nERROR tests/test_api.py - AssertionError\nERROR tests/test_education_service.py\nERROR tests/test_knowledge_assessment.py\n======================== 2 warnings, 6 errors in 1.18s =========================\n",
      "stderr": "ERROR: Wrong expression passed to '-k': test_*integration*.py: at column 6: unexpected character \"*\"\n\n",
      "total_tests": 0,
      "passed_tests": 0,
      "failed_tests": 0,
      "skipped_tests": 0
    },
    "agricultural_validation": {
      "category": "agricultural_validation",
      "success": false,
      "returncode": 4,
      "duration": 4.739739179611206,
      "stdout": "============================= test session starts ==============================\nplatform darwin -- Python 3.13.7, pytest-8.4.1, pluggy-1.6.0 -- /opt/homebrew/opt/python@3.13/bin/python3.13\ncachedir: .pytest_cache\nmetadata: {'Python': '3.13.7', 'Platform': 'macOS-26.0.1-arm64-arm-64bit-Mach-O', 'Packages': {'pytest': '8.4.1', 'pluggy': '1.6.0'}, 'Plugins': {'anyio': '4.9.0', 'html': '4.1.1', 'asyncio': '1.1.0', 'xdist': '3.8.0', 'metadata': '3.1.1', 'cov': '6.2.1', 'mock': '3.14.1'}}\nrootdir: /Users/Mark/Research/CAAIN_Soil_Hub/CAAIN_Soil_Hub_ChatGPT_Kiro/services/fertilizer-application\nconfigfile: pytest.ini\nplugins: anyio-4.9.0, html-4.1.1, asyncio-1.1.0, xdist-3.8.0, metadata-3.1.1, cov-6.2.1, mock-3.14.1\nasyncio: mode=Mode.AUTO, asyncio_default_fixture_loop_scope=None, asyncio_default_test_loop_scope=function\ncollecting ... collected 221 items / 6 errors\n\n==================================== ERRORS ====================================\n___________ ERROR collecting tests/test_adaptive_learning_service.py ___________\nImportError while importing test module '/Users/Mark/Research/CAAIN_Soil_Hub/CAAIN_Soil_Hub_ChatGPT_Kiro/services/fertilizer-application/tests/test_adaptive_learning_service.py'.\nHint: make sure your test modules/packages have valid Python names.\nTraceback:\n/opt/homebrew/lib/python3.13/site-packages/_pytest/python.py:498: in importtestmodule\n    mod = import_path(\n/opt/homebrew/lib/python3.13/site-packages/_pytest/pathlib.py:587: in import_path\n    importlib.import_module(module_name)\n/opt/homebrew/Cellar/python@3.13/3.13.7/Frameworks/Python.framework/Versions/3.13/lib/python3.13/importlib/__init__.py:88: in import_module\n    return _bootstrap._gcd_import(name[level:], package, level)\n           ^^^^^^^^^^^^^^^^^^^^^^^^^^^^^^^^^^^^^^^^^^^^^^^^^^^^\n<frozen importlib._bootstrap>:1387: in _gcd_import\n    ???\n<frozen importlib._bootstrap>:1360: in _find_and_load\n    ???\n<frozen importlib._bootstrap>:1331: in _find_and_load_unlocked\n    ???\n<frozen importlib._bootstrap>:935: in _load_unlocked\n    ???\n/opt/homebrew/lib/python3.13/site-packages/_pytest/assertion/rewrite.py:186: in exec_module\n    exec(co, module.__dict__)\ntests/test_adaptive_learning_service.py:15: in <module>\n    from src.services.adaptive_learning_service import (\nsrc/services/adaptive_learning_service.py:35: in <module>\n    from src.servicesgoal_based_recommendation_engine import GoalBasedRecommendationEngine, OptimizationGoal\nE   ModuleNotFoundError: No module named 'src.servicesgoal_based_recommendation_engine'\n________ ERROR collecting tests/test_advanced_application_endpoints.py _________\ntests/test_advanced_application_endpoints.py:13: in <module>\n    from src.main import app\nsrc/main.py:17: in <module>\n    from src.api.crop_response_routes import router as crop_response_router\nsrc/api/crop_response_routes.py:32: in <module>\n    @router.post(\"/optimize-methods\", response_model=List[Dict[str, Any]])\n     ^^^^^^^^^^^^^^^^^^^^^^^^^^^^^^^^^^^^^^^^^^^^^^^^^^^^^^^^^^^^^^^^^^^^^\n/opt/homebrew/lib/python3.13/site-packages/fastapi/routing.py:995: in decorator\n    self.add_api_route(\n/opt/homebrew/lib/python3.13/site-packages/fastapi/routing.py:934: in add_api_route\n    route = route_class(\n/opt/homebrew/lib/python3.13/site-packages/fastapi/routing.py:555: in __init__\n    self.dependant = get_dependant(path=self.path_format, call=self.endpoint)\n                     ^^^^^^^^^^^^^^^^^^^^^^^^^^^^^^^^^^^^^^^^^^^^^^^^^^^^^^^^\n/opt/homebrew/lib/python3.13/site-packages/fastapi/dependencies/utils.py:285: in get_dependant\n    param_details = analyze_param(\n/opt/homebrew/lib/python3.13/site-packages/fastapi/dependencies/utils.py:502: in analyze_param\n    is_scalar_field(field)\nE   AssertionError\n_________ ERROR collecting tests/test_algorithm_validation_service.py __________\nImportError while importing test module '/Users/Mark/Research/CAAIN_Soil_Hub/CAAIN_Soil_Hub_ChatGPT_Kiro/services/fertilizer-application/tests/test_algorithm_validation_service.py'.\nHint: make sure your test modules/packages have valid Python names.\nTraceback:\n/opt/homebrew/lib/python3.13/site-packages/_pytest/python.py:498: in importtestmodule\n    mod = import_path(\n/opt/homebrew/lib/python3.13/site-packages/_pytest/pathlib.py:587: in import_path\n    importlib.import_module(module_name)\n/opt/homebrew/Cellar/python@3.13/3.13.7/Frameworks/Python.framework/Versions/3.13/lib/python3.13/importlib/__init__.py:88: in import_module\n    return _bootstrap._gcd_import(name[level:], package, level)\n           ^^^^^^^^^^^^^^^^^^^^^^^^^^^^^^^^^^^^^^^^^^^^^^^^^^^^\n<frozen importlib._bootstrap>:1387: in _gcd_import\n    ???\n<frozen importlib._bootstrap>:1360: in _find_and_load\n    ???\n<frozen importlib._bootstrap>:1331: in _find_and_load_unlocked\n    ???\n<frozen importlib._bootstrap>:935: in _load_unlocked\n    ???\n/opt/homebrew/lib/python3.13/site-packages/_pytest/assertion/rewrite.py:186: in exec_module\n    exec(co, module.__dict__)\ntests/test_algorithm_validation_service.py:26: in <module>\n    from src.services.sophisticated_method_selection_service import (\nsrc/services/sophisticated_method_selection_service.py:29: in <module>\n    import cvxpy as cp\nE   ModuleNotFoundError: No module named 'cvxpy'\n______________________ ERROR collecting tests/test_api.py ______________________\ntests/test_api.py:10: in <module>\n    from src.main import app\nsrc/main.py:17: in <module>\n    from src.api.crop_response_routes import router as crop_response_router\nsrc/api/crop_response_routes.py:32: in <module>\n    @router.post(\"/optimize-methods\", response_model=List[Dict[str, Any]])\n     ^^^^^^^^^^^^^^^^^^^^^^^^^^^^^^^^^^^^^^^^^^^^^^^^^^^^^^^^^^^^^^^^^^^^^\n/opt/homebrew/lib/python3.13/site-packages/fastapi/routing.py:995: in decorator\n    self.add_api_route(\n/opt/homebrew/lib/python3.13/site-packages/fastapi/routing.py:934: in add_api_route\n    route = route_class(\n/opt/homebrew/lib/python3.13/site-packages/fastapi/routing.py:555: in __init__\n    self.dependant = get_dependant(path=self.path_format, call=self.endpoint)\n                     ^^^^^^^^^^^^^^^^^^^^^^^^^^^^^^^^^^^^^^^^^^^^^^^^^^^^^^^^\n/opt/homebrew/lib/python3.13/site-packages/fastapi/dependencies/utils.py:285: in get_dependant\n    param_details = analyze_param(\n/opt/homebrew/lib/python3.13/site-packages/fastapi/dependencies/utils.py:502: in analyze_param\n    is_scalar_field(field)\nE   AssertionError\n_______________ ERROR collecting tests/test_education_service.py _______________\nImportError while importing test module '/Users/Mark/Research/CAAIN_Soil_Hub/CAAIN_Soil_Hub_ChatGPT_Kiro/services/fertilizer-application/tests/test_education_service.py'.\nHint: make sure your test modules/packages have valid Python names.\nTraceback:\n/opt/homebrew/lib/python3.13/site-packages/_pytest/python.py:498: in importtestmodule\n    mod = import_path(\n/opt/homebrew/lib/python3.13/site-packages/_pytest/pathlib.py:587: in import_path\n    importlib.import_module(module_name)\n/opt/homebrew/Cellar/python@3.13/3.13.7/Frameworks/Python.framework/Versions/3.13/lib/python3.13/importlib/__init__.py:88: in import_module\n    return _bootstrap._gcd_import(name[level:], package, level)\n           ^^^^^^^^^^^^^^^^^^^^^^^^^^^^^^^^^^^^^^^^^^^^^^^^^^^^\n<frozen importlib._bootstrap>:1387: in _gcd_import\n    ???\n<frozen importlib._bootstrap>:1360: in _find_and_load\n    ???\n<frozen importlib._bootstrap>:1331: in _find_and_load_unlocked\n    ???\n<frozen importlib._bootstrap>:935: in _load_unlocked\n    ???\n/opt/homebrew/lib/python3.13/site-packages/_pytest/assertion/rewrite.py:186: in exec_module\n    exec(co, module.__dict__)\ntests/test_education_service.py:15: in <module>\n    from src.services.education_service import EducationService\nsrc/services/education_service.py:16: in <module>\n    from src.models.educational_models import (\nE   ImportError: cannot import name 'UserProfile' from 'src.models.educational_models' (/Users/Mark/Research/CAAIN_Soil_Hub/CAAIN_Soil_Hub_ChatGPT_Kiro/services/fertilizer-application/src/models/educational_models.py)\n_____________ ERROR collecting tests/test_knowledge_assessment.py ______________\nImportError while importing test module '/Users/Mark/Research/CAAIN_Soil_Hub/CAAIN_Soil_Hub_ChatGPT_Kiro/services/fertilizer-application/tests/test_knowledge_assessment.py'.\nHint: make sure your test modules/packages have valid Python names.\nTraceback:\n/opt/homebrew/lib/python3.13/site-packages/_pytest/python.py:498: in importtestmodule\n    mod = import_path(\n/opt/homebrew/lib/python3.13/site-packages/_pytest/pathlib.py:587: in import_path\n    importlib.import_module(module_name)\n/opt/homebrew/Cellar/python@3.13/3.13.7/Frameworks/Python.framework/Versions/3.13/lib/python3.13/importlib/__init__.py:88: in import_module\n    return _bootstrap._gcd_import(name[level:], package, level)\n           ^^^^^^^^^^^^^^^^^^^^^^^^^^^^^^^^^^^^^^^^^^^^^^^^^^^^\n<frozen importlib._bootstrap>:1387: in _gcd_import\n    ???\n<frozen importlib._bootstrap>:1360: in _find_and_load\n    ???\n<frozen importlib._bootstrap>:1331: in _find_and_load_unlocked\n    ???\n<frozen importlib._bootstrap>:935: in _load_unlocked\n    ???\n/opt/homebrew/lib/python3.13/site-packages/_pytest/assertion/rewrite.py:186: in exec_module\n    exec(co, module.__dict__)\ntests/test_knowledge_assessment.py:14: in <module>\n    from src.models.educational_models import (\nE   ImportError: cannot import name 'CertificationStatus' from 'src.models.educational_models' (/Users/Mark/Research/CAAIN_Soil_Hub/CAAIN_Soil_Hub_ChatGPT_Kiro/services/fertilizer-application/src/models/educational_models.py)\n- generated xml file: /Users/Mark/Research/CAAIN_Soil_Hub/CAAIN_Soil_Hub_ChatGPT_Kiro/services/fertilizer-application/test_reports/agricultural_validation_results.xml -\n- Generated html report: file:///Users/Mark/Research/CAAIN_Soil_Hub/CAAIN_Soil_Hub_ChatGPT_Kiro/services/fertilizer-application/test_reports/agricultural_validation_report.html -\n=========================== short test summary info ============================\nERROR tests/test_adaptive_learning_service.py\nERROR tests/test_advanced_application_endpoints.py - AssertionError\nERROR tests/test_algorithm_validation_service.py\nERROR tests/test_api.py - AssertionError\nERROR tests/test_education_service.py\nERROR tests/test_knowledge_assessment.py\n======================== 2 warnings, 6 errors in 1.15s =========================\n",
      "stderr": "ERROR: Wrong expression passed to '-k': test_agricultural*.py: at column 18: unexpected character \"*\"\n\n",
      "total_tests": 0,
      "passed_tests": 0,
      "failed_tests": 0,
      "skipped_tests": 0
    },
    "comprehensive": {
      "category": "comprehensive",
      "success": false,
      "returncode": 4,
      "duration": 4.721816062927246,
      "stdout": "============================= test session starts ==============================\nplatform darwin -- Python 3.13.7, pytest-8.4.1, pluggy-1.6.0 -- /opt/homebrew/opt/python@3.13/bin/python3.13\ncachedir: .pytest_cache\nmetadata: {'Python': '3.13.7', 'Platform': 'macOS-26.0.1-arm64-arm-64bit-Mach-O', 'Packages': {'pytest': '8.4.1', 'pluggy': '1.6.0'}, 'Plugins': {'anyio': '4.9.0', 'html': '4.1.1', 'asyncio': '1.1.0', 'xdist': '3.8.0', 'metadata': '3.1.1', 'cov': '6.2.1', 'mock': '3.14.1'}}\nrootdir: /Users/Mark/Research/CAAIN_Soil_Hub/CAAIN_Soil_Hub_ChatGPT_Kiro/services/fertilizer-application\nconfigfile: pytest.ini\nplugins: anyio-4.9.0, html-4.1.1, asyncio-1.1.0, xdist-3.8.0, metadata-3.1.1, cov-6.2.1, mock-3.14.1\nasyncio: mode=Mode.AUTO, asyncio_default_fixture_loop_scope=None, asyncio_default_test_loop_scope=function\ncollecting ... collected 221 items / 6 errors\n\n==================================== ERRORS ====================================\n___________ ERROR collecting tests/test_adaptive_learning_service.py ___________\nImportError while importing test module '/Users/Mark/Research/CAAIN_Soil_Hub/CAAIN_Soil_Hub_ChatGPT_Kiro/services/fertilizer-application/tests/test_adaptive_learning_service.py'.\nHint: make sure your test modules/packages have valid Python names.\nTraceback:\n/opt/homebrew/lib/python3.13/site-packages/_pytest/python.py:498: in importtestmodule\n    mod = import_path(\n/opt/homebrew/lib/python3.13/site-packages/_pytest/pathlib.py:587: in import_path\n    importlib.import_module(module_name)\n/opt/homebrew/Cellar/python@3.13/3.13.7/Frameworks/Python.framework/Versions/3.13/lib/python3.13/importlib/__init__.py:88: in import_module\n    return _bootstrap._gcd_import(name[level:], package, level)\n           ^^^^^^^^^^^^^^^^^^^^^^^^^^^^^^^^^^^^^^^^^^^^^^^^^^^^\n<frozen importlib._bootstrap>:1387: in _gcd_import\n    ???\n<frozen importlib._bootstrap>:1360: in _find_and_load\n    ???\n<frozen importlib._bootstrap>:1331: in _find_and_load_unlocked\n    ???\n<frozen importlib._bootstrap>:935: in _load_unlocked\n    ???\n/opt/homebrew/lib/python3.13/site-packages/_pytest/assertion/rewrite.py:186: in exec_module\n    exec(co, module.__dict__)\ntests/test_adaptive_learning_service.py:15: in <module>\n    from src.services.adaptive_learning_service import (\nsrc/services/adaptive_learning_service.py:35: in <module>\n    from src.servicesgoal_based_recommendation_engine import GoalBasedRecommendationEngine, OptimizationGoal\nE   ModuleNotFoundError: No module named 'src.servicesgoal_based_recommendation_engine'\n________ ERROR collecting tests/test_advanced_application_endpoints.py _________\ntests/test_advanced_application_endpoints.py:13: in <module>\n    from src.main import app\nsrc/main.py:17: in <module>\n    from src.api.crop_response_routes import router as crop_response_router\nsrc/api/crop_response_routes.py:32: in <module>\n    @router.post(\"/optimize-methods\", response_model=List[Dict[str, Any]])\n     ^^^^^^^^^^^^^^^^^^^^^^^^^^^^^^^^^^^^^^^^^^^^^^^^^^^^^^^^^^^^^^^^^^^^^\n/opt/homebrew/lib/python3.13/site-packages/fastapi/routing.py:995: in decorator\n    self.add_api_route(\n/opt/homebrew/lib/python3.13/site-packages/fastapi/routing.py:934: in add_api_route\n    route = route_class(\n/opt/homebrew/lib/python3.13/site-packages/fastapi/routing.py:555: in __init__\n    self.dependant = get_dependant(path=self.path_format, call=self.endpoint)\n                     ^^^^^^^^^^^^^^^^^^^^^^^^^^^^^^^^^^^^^^^^^^^^^^^^^^^^^^^^\n/opt/homebrew/lib/python3.13/site-packages/fastapi/dependencies/utils.py:285: in get_dependant\n    param_details = analyze_param(\n/opt/homebrew/lib/python3.13/site-packages/fastapi/dependencies/utils.py:502: in analyze_param\n    is_scalar_field(field)\nE   AssertionError\n_________ ERROR collecting tests/test_algorithm_validation_service.py __________\nImportError while importing test module '/Users/Mark/Research/CAAIN_Soil_Hub/CAAIN_Soil_Hub_ChatGPT_Kiro/services/fertilizer-application/tests/test_algorithm_validation_service.py'.\nHint: make sure your test modules/packages have valid Python names.\nTraceback:\n/opt/homebrew/lib/python3.13/site-packages/_pytest/python.py:498: in importtestmodule\n    mod = import_path(\n/opt/homebrew/lib/python3.13/site-packages/_pytest/pathlib.py:587: in import_path\n    importlib.import_module(module_name)\n/opt/homebrew/Cellar/python@3.13/3.13.7/Frameworks/Python.framework/Versions/3.13/lib/python3.13/importlib/__init__.py:88: in import_module\n    return _bootstrap._gcd_import(name[level:], package, level)\n           ^^^^^^^^^^^^^^^^^^^^^^^^^^^^^^^^^^^^^^^^^^^^^^^^^^^^\n<frozen importlib._bootstrap>:1387: in _gcd_import\n    ???\n<frozen importlib._bootstrap>:1360: in _find_and_load\n    ???\n<frozen importlib._bootstrap>:1331: in _find_and_load_unlocked\n    ???\n<frozen importlib._bootstrap>:935: in _load_unlocked\n    ???\n/opt/homebrew/lib/python3.13/site-packages/_pytest/assertion/rewrite.py:186: in exec_module\n    exec(co, module.__dict__)\ntests/test_algorithm_validation_service.py:26: in <module>\n    from src.services.sophisticated_method_selection_service import (\nsrc/services/sophisticated_method_selection_service.py:29: in <module>\n    import cvxpy as cp\nE   ModuleNotFoundError: No module named 'cvxpy'\n______________________ ERROR collecting tests/test_api.py ______________________\ntests/test_api.py:10: in <module>\n    from src.main import app\nsrc/main.py:17: in <module>\n    from src.api.crop_response_routes import router as crop_response_router\nsrc/api/crop_response_routes.py:32: in <module>\n    @router.post(\"/optimize-methods\", response_model=List[Dict[str, Any]])\n     ^^^^^^^^^^^^^^^^^^^^^^^^^^^^^^^^^^^^^^^^^^^^^^^^^^^^^^^^^^^^^^^^^^^^^\n/opt/homebrew/lib/python3.13/site-packages/fastapi/routing.py:995: in decorator\n    self.add_api_route(\n/opt/homebrew/lib/python3.13/site-packages/fastapi/routing.py:934: in add_api_route\n    route = route_class(\n/opt/homebrew/lib/python3.13/site-packages/fastapi/routing.py:555: in __init__\n    self.dependant = get_dependant(path=self.path_format, call=self.endpoint)\n                     ^^^^^^^^^^^^^^^^^^^^^^^^^^^^^^^^^^^^^^^^^^^^^^^^^^^^^^^^\n/opt/homebrew/lib/python3.13/site-packages/fastapi/dependencies/utils.py:285: in get_dependant\n    param_details = analyze_param(\n/opt/homebrew/lib/python3.13/site-packages/fastapi/dependencies/utils.py:502: in analyze_param\n    is_scalar_field(field)\nE   AssertionError\n_______________ ERROR collecting tests/test_education_service.py _______________\nImportError while importing test module '/Users/Mark/Research/CAAIN_Soil_Hub/CAAIN_Soil_Hub_ChatGPT_Kiro/services/fertilizer-application/tests/test_education_service.py'.\nHint: make sure your test modules/packages have valid Python names.\nTraceback:\n/opt/homebrew/lib/python3.13/site-packages/_pytest/python.py:498: in importtestmodule\n    mod = import_path(\n/opt/homebrew/lib/python3.13/site-packages/_pytest/pathlib.py:587: in import_path\n    importlib.import_module(module_name)\n/opt/homebrew/Cellar/python@3.13/3.13.7/Frameworks/Python.framework/Versions/3.13/lib/python3.13/importlib/__init__.py:88: in import_module\n    return _bootstrap._gcd_import(name[level:], package, level)\n           ^^^^^^^^^^^^^^^^^^^^^^^^^^^^^^^^^^^^^^^^^^^^^^^^^^^^\n<frozen importlib._bootstrap>:1387: in _gcd_import\n    ???\n<frozen importlib._bootstrap>:1360: in _find_and_load\n    ???\n<frozen importlib._bootstrap>:1331: in _find_and_load_unlocked\n    ???\n<frozen importlib._bootstrap>:935: in _load_unlocked\n    ???\n/opt/homebrew/lib/python3.13/site-packages/_pytest/assertion/rewrite.py:186: in exec_module\n    exec(co, module.__dict__)\ntests/test_education_service.py:15: in <module>\n    from src.services.education_service import EducationService\nsrc/services/education_service.py:16: in <module>\n    from src.models.educational_models import (\nE   ImportError: cannot import name 'UserProfile' from 'src.models.educational_models' (/Users/Mark/Research/CAAIN_Soil_Hub/CAAIN_Soil_Hub_ChatGPT_Kiro/services/fertilizer-application/src/models/educational_models.py)\n_____________ ERROR collecting tests/test_knowledge_assessment.py ______________\nImportError while importing test module '/Users/Mark/Research/CAAIN_Soil_Hub/CAAIN_Soil_Hub_ChatGPT_Kiro/services/fertilizer-application/tests/test_knowledge_assessment.py'.\nHint: make sure your test modules/packages have valid Python names.\nTraceback:\n/opt/homebrew/lib/python3.13/site-packages/_pytest/python.py:498: in importtestmodule\n    mod = import_path(\n/opt/homebrew/lib/python3.13/site-packages/_pytest/pathlib.py:587: in import_path\n    importlib.import_module(module_name)\n/opt/homebrew/Cellar/python@3.13/3.13.7/Frameworks/Python.framework/Versions/3.13/lib/python3.13/importlib/__init__.py:88: in import_module\n    return _bootstrap._gcd_import(name[level:], package, level)\n           ^^^^^^^^^^^^^^^^^^^^^^^^^^^^^^^^^^^^^^^^^^^^^^^^^^^^\n<frozen importlib._bootstrap>:1387: in _gcd_import\n    ???\n<frozen importlib._bootstrap>:1360: in _find_and_load\n    ???\n<frozen importlib._bootstrap>:1331: in _find_and_load_unlocked\n    ???\n<frozen importlib._bootstrap>:935: in _load_unlocked\n    ???\n/opt/homebrew/lib/python3.13/site-packages/_pytest/assertion/rewrite.py:186: in exec_module\n    exec(co, module.__dict__)\ntests/test_knowledge_assessment.py:14: in <module>\n    from src.models.educational_models import (\nE   ImportError: cannot import name 'CertificationStatus' from 'src.models.educational_models' (/Users/Mark/Research/CAAIN_Soil_Hub/CAAIN_Soil_Hub_ChatGPT_Kiro/services/fertilizer-application/src/models/educational_models.py)\n- generated xml file: /Users/Mark/Research/CAAIN_Soil_Hub/CAAIN_Soil_Hub_ChatGPT_Kiro/services/fertilizer-application/test_reports/comprehensive_results.xml -\n- Generated html report: file:///Users/Mark/Research/CAAIN_Soil_Hub/CAAIN_Soil_Hub_ChatGPT_Kiro/services/fertilizer-application/test_reports/comprehensive_report.html -\n=========================== short test summary info ============================\nERROR tests/test_adaptive_learning_service.py\nERROR tests/test_advanced_application_endpoints.py - AssertionError\nERROR tests/test_algorithm_validation_service.py\nERROR tests/test_api.py - AssertionError\nERROR tests/test_education_service.py\nERROR tests/test_knowledge_assessment.py\n======================== 2 warnings, 6 errors in 1.15s =========================\n",
      "stderr": "ERROR: Wrong expression passed to '-k': test_comprehensive*.py: at column 19: unexpected character \"*\"\n\n",
      "total_tests": 0,
      "passed_tests": 0,
      "failed_tests": 0,
      "skipped_tests": 0
    }
  },
  "overall_success": false,
  "total_tests": 0,
  "passed_tests": 0,
  "failed_tests": 0,
  "skipped_tests": 0,
  "coverage_percentage": 0.0,
  "performance_metrics": {},
  "end_time": 1759235223.5261009,
  "duration": 19.634922981262207
}